<?xml version="1.0"?>
<robot name="ur5_leap_right">

    <!-- links: main serial chain -->
    <link name="base_link" />
    <link name="base_link_inertia">
        <visual>
            <origin rpy="0 0 3.141592653589793" xyz="0 0 0" />
            <geometry>
                <mesh filename="meshes/ur5/visual/base.dae" />
            </geometry>
            <material name="LightGrey">
                <color rgba="0.7 0.7 0.7 1.0" />
            </material>
        </visual>
        <collision>
            <origin rpy="0 0 3.141592653589793" xyz="0 0 0" />
            <geometry>
                <mesh filename="meshes/ur5/collision/base.stl" />
            </geometry>
        </collision>
        <inertial>
            <mass value="4.0" />
            <origin rpy="0 0 0" xyz="0 0 0" />
            <inertia ixx="0.00443333156" ixy="0.0" ixz="0.0" iyy="0.00443333156" iyz="0.0"
                izz="0.0072" />
        </inertial>
    </link>
    <link name="shoulder_link">
        <visual>
            <origin rpy="0 0 3.141592653589793" xyz="0 0 0" />
            <geometry>
                <mesh filename="meshes/ur5/visual/shoulder.dae" />
            </geometry>
            <material name="LightGrey">
                <color rgba="0.7 0.7 0.7 1.0" />
            </material>
        </visual>
        <collision>
            <origin rpy="0 0 3.141592653589793" xyz="0 0 0" />
            <geometry>
                <mesh filename="meshes/ur5/collision/shoulder.stl" />
            </geometry>
        </collision>
        <inertial>
            <mass value="3.7" />
            <origin rpy="0 0 0" xyz="0 0 0" />
            <inertia ixx="0.014972352344389999" ixy="0.0" ixz="0.0" iyy="0.014972352344389999"
                iyz="0.0" izz="0.01040625" />
        </inertial>
    </link>
    <link name="upper_arm_link">
        <visual>
            <origin rpy="1.5707963267948966 0 -1.5707963267948966" xyz="0 0 0.13585" />
            <geometry>
                <mesh filename="meshes/ur5/visual/upperarm.dae" />
            </geometry>
            <material name="LightGrey">
                <color rgba="0.7 0.7 0.7 1.0" />
            </material>
        </visual>
        <collision>
            <origin rpy="1.5707963267948966 0 -1.5707963267948966" xyz="0 0 0.13585" />
            <geometry>
                <mesh filename="meshes/ur5/collision/upperarm.stl" />
            </geometry>
        </collision>
        <inertial>
            <mass value="8.393" />
            <origin rpy="0 1.5707963267948966 0" xyz="-0.2125 0.0 0.136" />
            <inertia ixx="0.1338857818623325" ixy="0.0" ixz="0.0" iyy="0.1338857818623325" iyz="0.0"
                izz="0.0151074" />
        </inertial>
    </link>
    <link name="forearm_link">
        <visual>
            <origin rpy="1.5707963267948966 0 -1.5707963267948966" xyz="0 0 0.0165" />
            <geometry>
                <mesh filename="meshes/ur5/visual/forearm.dae" />
            </geometry>
            <material name="LightGrey">
                <color rgba="0.7 0.7 0.7 1.0" />
            </material>
        </visual>
        <collision>
            <origin rpy="1.5707963267948966 0 -1.5707963267948966" xyz="0 0 0.0165" />
            <geometry>
                <mesh filename="meshes/ur5/collision/forearm.stl" />
            </geometry>
        </collision>
        <inertial>
            <mass value="2.275" />
            <origin rpy="0 1.5707963267948966 0" xyz="-0.196125 0.0 0.0165" />
            <inertia ixx="0.03121679102890359" ixy="0.0" ixz="0.0" iyy="0.03121679102890359"
                iyz="0.0" izz="0.004095" />
        </inertial>
    </link>
    <link name="wrist_1_link">
        <visual>
            <!-- TODO: Move this to a parameter -->
            <origin rpy="1.5707963267948966 0 0" xyz="0 0 -0.093" />
            <geometry>
                <mesh filename="meshes/ur5/visual/wrist1.dae" />
            </geometry>
            <material name="LightGrey">
                <color rgba="0.7 0.7 0.7 1.0" />
            </material>
        </visual>
        <collision>
            <origin rpy="1.5707963267948966 0 0" xyz="0 0 -0.093" />
            <geometry>
                <mesh filename="meshes/ur5/collision/wrist1.stl" />
            </geometry>
        </collision>
        <inertial>
            <mass value="1.219" />
            <origin rpy="0 0 0" xyz="0 0 0" />
            <inertia ixx="0.0020138887777775" ixy="0.0" ixz="0.0" iyy="0.0020138887777775" iyz="0.0"
                izz="0.0021942" />
        </inertial>
    </link>
    <link name="wrist_2_link">
        <visual>
            <origin rpy="0 0 0" xyz="0 0 -0.095" />
            <geometry>
                <mesh filename="meshes/ur5/visual/wrist2.dae" />
            </geometry>
            <material name="LightGrey">
                <color rgba="0.7 0.7 0.7 1.0" />
            </material>
        </visual>
        <collision>
            <origin rpy="0 0 0" xyz="0 0 -0.095" />
            <geometry>
                <mesh filename="meshes/ur5/collision/wrist2.stl" />
            </geometry>
        </collision>
        <inertial>
            <mass value="1.219" />
            <origin rpy="0 0 0" xyz="0 0 0" />
            <inertia ixx="0.0018310388509175" ixy="0.0" ixz="0.0" iyy="0.0018310388509175" iyz="0.0"
                izz="0.0021942" />
        </inertial>
    </link>
    <link name="wrist_3_link">
        <visual>
            <origin rpy="1.5707963267948966 0 0" xyz="0 0 -0.0818" />
            <geometry>
                <mesh filename="meshes/ur5/visual/wrist3.dae" />
            </geometry>
            <material name="LightGrey">
                <color rgba="0.7 0.7 0.7 1.0" />
            </material>
        </visual>
        <collision>
            <origin rpy="1.5707963267948966 0 0" xyz="0 0 -0.0818" />
            <geometry>
                <mesh filename="meshes/ur5/collision/wrist3.stl" />
            </geometry>
        </collision>
        <inertial>
            <mass value="0.1879" />
            <origin rpy="0 0 0" xyz="0.0 0.0 -0.01525" />
            <inertia ixx="8.062472608343e-05" ixy="0.0" ixz="0.0" iyy="8.062472608343e-05" iyz="0.0"
                izz="0.0001321171875" />
        </inertial>
    </link>
    <!-- joints: main serial chain -->
    <joint name="base_link-base_link_inertia" type="fixed">
        <parent link="base_link" />
        <child link="base_link_inertia" />
        <!-- 'base_link' is REP-103 aligned (so X+ forward), while the internal
           frames of the robot/controller have X+ pointing backwards.
           Use the joint between 'base_link' and 'base_link_inertia' (a dummy
           link/frame) to introduce the necessary rotation over Z (of pi rad).
      -->
        <origin rpy="0 0 3.141592653589793" xyz="0 0 0" />
    </joint>
    <joint name="shoulder_pan_joint" type="revolute">
        <parent link="base_link_inertia" />
        <child link="shoulder_link" />
        <origin rpy="0 0 0" xyz="0 0 0.089159" />
        <axis xyz="0 0 1" />
        <limit effort="150.0" lower="-6.283185307179586" upper="6.283185307179586"
            velocity="3.141592653589793" />
        <dynamics damping="0" friction="0" />
    </joint>
    <joint name="shoulder_lift_joint" type="revolute">
        <parent link="shoulder_link" />
        <child link="upper_arm_link" />
        <origin rpy="1.570796327 0 0" xyz="0 0 0" />
        <axis xyz="0 0 1" />
        <limit effort="150.0" lower="-6.283185307179586" upper="6.283185307179586"
            velocity="3.141592653589793" />
        <dynamics damping="0" friction="0" />
    </joint>
    <joint name="elbow_joint" type="revolute">
        <parent link="upper_arm_link" />
        <child link="forearm_link" />
        <origin rpy="0 0 0" xyz="-0.425 0 0" />
        <axis xyz="0 0 1" />
        <limit effort="150.0" lower="-3.141592653589793" upper="3.141592653589793"
            velocity="3.141592653589793" />
        <dynamics damping="0" friction="0" />
    </joint>
    <joint name="wrist_1_joint" type="revolute">
        <parent link="forearm_link" />
        <child link="wrist_1_link" />
        <origin rpy="0 0 0" xyz="-0.39225 0 0.10915" />
        <axis xyz="0 0 1" />
        <limit effort="28.0" lower="-6.283185307179586" upper="6.283185307179586"
            velocity="3.141592653589793" />
        <dynamics damping="0" friction="0" />
    </joint>
    <joint name="wrist_2_joint" type="revolute">
        <parent link="wrist_1_link" />
        <child link="wrist_2_link" />
        <origin rpy="1.570796327 0 0" xyz="0 -0.09465 -1.941303950897609e-11" />
        <axis xyz="0 0 1" />
        <limit effort="28.0" lower="-6.283185307179586" upper="6.283185307179586"
            velocity="3.141592653589793" />
        <dynamics damping="0" friction="0" />
    </joint>
    <joint name="wrist_3_joint" type="revolute">
        <parent link="wrist_2_link" />
        <child link="wrist_3_link" />
        <origin rpy="1.570796326589793 3.141592653589793 3.141592653589793"
            xyz="0 0.0823 -1.688001216681175e-11" />
        <axis xyz="0 0 1" />
        <limit effort="28.0" lower="-6.283185307179586" upper="6.283185307179586"
            velocity="3.141592653589793" />
        <dynamics damping="0" friction="0" />
    </joint>
    <!-- ROS-Industrial 'base' frame: base_link to UR 'Base' Coordinates transform -->
    <link name="base" />
    <joint name="base_link-base_fixed_joint" type="fixed">
        <!-- Note the rotation over Z of pi radians: as base_link is REP-103
           aligned (ie: has X+ forward, Y+ left and Z+ up), this is needed
           to correctly align 'base' with the 'Base' coordinate system of
           the UR controller.
      -->
        <origin rpy="0 0 3.141592653589793" xyz="0 0 0" />
        <parent link="base_link" />
        <child link="base" />
    </joint>
    <!-- ROS-Industrial 'flange' frame: attachment point for EEF models -->
    <link name="flange" />
    <joint name="wrist_3-flange" type="fixed">
        <parent link="wrist_3_link" />
        <child link="flange" />
        <origin rpy="0 -1.5707963267948966 -1.5707963267948966" xyz="0 0 0" />
    </joint>
    <!-- ROS-Industrial 'tool0' frame: all-zeros tool frame -->
    <link name="tool0" />
    <joint name="flange-tool0" type="fixed">
        <!-- default toolframe: X+ left, Y+ up, Z+ front -->
        <origin rpy="1.5707963267948966 0 1.5707963267948966" xyz="0 0 0" />
        <parent link="flange" />
        <child link="tool0" />
    </joint>

    <joint name="ee_fixed_joint" type="fixed">
        <origin xyz="0 0 0.002" rpy="3.14159265 0 -1.57079632679" />
        <parent link="tool0" />
        <child link="mount" />
    </joint>

    <link name="mount" />
    <joint name="base_joint" type="fixed">
        <parent link="mount" />
        <child link="palm_lower" />
        <origin xyz="0.058 0.034 -0.048" rpy="0 0 0" />
    </joint>

    <link name="palm_lower">
        <visual>
            <origin xyz="-0.0200 0.02575 -0.0347" rpy="0 0 0" />
            <geometry>
                <!-- <mesh filename="meshes/leap/palm_lower.obj"/> -->
                <mesh filename="meshes/leap/palm_pack.obj" />
            </geometry>
        </visual>
        <collision>            <!-- palm_lower -->
            <origin xyz="-0.009 0.008 -0.011" rpy="0 0 0" />
            <geometry>
                <box size="0.022 0.026 0.034" />
            </geometry>
        </collision>
        <collision>
            <origin xyz="-0.009 -0.037 -0.011" rpy="0 0 0" />
            <geometry>
                <box size="0.022 0.026 0.034" />
            </geometry>
        </collision>
        <collision>
            <origin xyz="-0.009 -0.082 -0.011" rpy="0 0 0" />
            <geometry>
                <box size="0.022 0.026 0.034" />
            </geometry>
        </collision>
        <collision>
            <origin xyz="-0.066 -0.078 0.0065" rpy="0 0 -0.2967" />
            <geometry>
                <box size="0.058 0.02 0.082" />
            </geometry>
        </collision>
        <collision>
            <origin xyz="-0.03 -0.035 0.015" rpy="0 0 0" />
            <geometry>
                <box size="0.02 0.12 0.066" />
            </geometry>
        </collision>
        <collision>
            <origin xyz="-0.032 -0.035 -0.024" rpy="0 0.785 0" />
            <geometry>
                <box size="0.01 0.12 0.02" />
            </geometry>
        </collision>
        <collision>
            <origin xyz="-0.048 -0.033 0.0065" rpy="0 0 0" />
            <geometry>
                <box size="0.024 0.116 0.082" />
            </geometry>
        </collision>
        <collision>
            <origin xyz="-0.078 -0.053 0.0065" rpy="0 0 0" />
            <geometry>
                <box size="0.044 0.052 0.082" />
            </geometry>
        </collision>
        <collision>
            <origin xyz="-0.098 -0.009 0.013" rpy="0 0 0" />
            <geometry>
                <box size="0.004 0.036 0.070" />
            </geometry>
        </collision>
        <collision>
            <origin xyz="-0.078 -0.003 0.028" rpy="0 0 0" />
            <geometry>
                <box size="0.044 0.056 0.040" />
            </geometry>
        </collision>
        <inertial>
            <origin xyz="0 0 0" rpy="0 0 0" />
            <mass value="0.237" />
            <inertia ixx="0.000354094" ixy="-0.000001193" ixz="-0.000002445" iyy="0.000260915"
                iyz="-0.000002905" izz="0.000529257" />
        </inertial>
    </link>
    <link name="mcp_joint">
        <visual>
            <origin xyz="0.0084 0.0077 0.01465" rpy="0 0 0" />
            <geometry>
                <mesh filename="meshes/leap/mcp_joint.obj" />
            </geometry>
        </visual>
        <collision>            <!-- mcp_joint -->
            <origin xyz="0 0.018 0.0147" rpy="0 0 0" />
            <geometry>
                <box size="0.02 0.006 0.034" />
            </geometry>
        </collision>
        <collision>
            <origin xyz="-0.027 0.042 0.015" rpy="0 0 0" />
            <geometry>
                <box size="0.028 0.04 0.02" />
            </geometry>
        </collision>
        <collision>
            <origin xyz="-0.0262 0.02 0.0146" rpy="0 0 0" />
            <geometry>
                <box size="0.034 0.006 0.02" />
            </geometry>
        </collision>
        <collision>
            <origin xyz="-0.0295 0.035 0.029" rpy="0 0 0" />
            <geometry>
                <box size="0.02 0.024 0.008" />
            </geometry>
        </collision>
        <collision>
            <origin xyz="0 0.005 0.03" rpy="0 0 0" />
            <geometry>
                <box size="0.014 0.02 0.004" />
            </geometry>
        </collision>
        <collision>
            <origin xyz="0 0.005 -0.001" rpy="0 0 0" />
            <geometry>
                <box size="0.014 0.02 0.004" />
            </geometry>
        </collision>
        <inertial>
            <origin xyz="0 0 0" rpy="0 0 0" />
            <mass value="0.044" />
            <inertia ixx="0.000011499" ixy="0.000003049" ixz="0.000000121" iyy="0.000007796"
                iyz="0.000000112" izz="0.000014759" />
        </inertial>
    </link>
    <link name="pip">
        <visual>
            <origin xyz="0.0096 0.0002 0.0007" rpy="-1.57079 -1.57079 0" />
            <geometry>
                <mesh filename="meshes/leap/pip.obj" />
            </geometry>
        </visual>
        <collision>            <!-- pip -->
            <origin xyz="0.0075 -0.0002 -0.011" rpy="0 0 0" />
            <geometry>
                <box size="0.034 0.026 0.022" />
            </geometry>
        </collision>
        <inertial>
            <origin xyz="0 0 0" rpy="0 0 0" />
            <mass value="0.032" />
            <inertia ixx="0.000004798" ixy="0.000000012" ixz="0.000000004" iyy="0.000002862"
                iyz="0.000000011" izz="0.000004234" />
        </inertial>
    </link>
    <link name="dip">
        <visual>
            <origin xyz="0.0211 -0.0084 0.0097" rpy="-3.1415926 0 0" />
            <geometry>
                <mesh filename="meshes/leap/dip.obj" />
            </geometry>
        </visual>
        <collision>            <!-- dip -->
            <origin xyz="0 -0.02 0.015" rpy="0 0 0" />
            <geometry>
                <box size="0.016 0.006 0.026" />
            </geometry>
        </collision>
        <collision>
            <origin xyz="0 -0.016 0.015" rpy="0 0 0" />
            <geometry>
                <box size="0.02 0.004 0.034" />
            </geometry>
        </collision>
        <collision>
            <origin xyz="0 -0.0045 0.03" rpy="0 0 0" />
            <geometry>
                <box size="0.014 0.02 0.004" />
            </geometry>
        </collision>
        <collision>
            <origin xyz="0 -0.0045 0" rpy="0 0 0" />
            <geometry>
                <box size="0.014 0.02 0.004" />
            </geometry>
        </collision>
        <collision>
            <origin xyz="0.0075 -0.035 0.015" rpy="0 0 0" />
            <geometry>
                <box size="0.034 0.022 0.026" />
            </geometry>
        </collision>
        <inertial>
            <origin xyz="0 0 0" rpy="0 0 0" />
            <mass value="0.037" />
            <inertia ixx="0.000005542" ixy="-0.000000607" ixz="-0.000000017" iyy="0.000005727"
                iyz="-0.000000023" izz="0.000006682" />
        </inertial>
    </link>
    <link name="tip_base">
        <visual>
            <origin xyz="0 -0.014 0.014499" rpy="3.14159 0 0 " />
            <geometry>
                <mesh filename="./meshes/leap/tip_base.obj" />
            </geometry>
        </visual>
        <collision>
            <origin xyz="0 -0.017 0.015" rpy="0 0 0" />
            <geometry>
                <box size="0.02 0.006 0.03" />
            </geometry>
        </collision>
        <collision>
            <origin xyz="0 -0.006 0.03" rpy="0 0 0" />
            <geometry>
                <box size="0.014 0.022 0.004" />
            </geometry>
        </collision>
        <collision>
            <origin xyz="0 -0.006 -0.001" rpy="0 0 0" />
            <geometry>
                <box size="0.014 0.022 0.004" />
            </geometry>
        </collision>
        <inertial>
            <origin xyz="0 0 0" rpy="0 0 0" />
            <mass value="0.008" />
            <inertia ixx="0.000003368" ixy="0.000000115" ixz="0" iyy="0.000001556" iyz="0"
                izz="0.000002863" />
        </inertial>
    </link>
    <link name="fingertip_if">
        <visual>
            <origin xyz="0 0 0" rpy="3.14159 0 -1.57080" />
            <geometry>
                <mesh filename="./meshes/leap/DotTip.dae" />
            </geometry>
        </visual>
        <collision>
            <origin xyz="0 0 0" rpy="3.14159 0 -1.57080" />
            <geometry>
                <mesh filename="./meshes/leap/DotTip.dae" />
            </geometry>
        </collision>
        <inertial>
            <origin xyz="0 0 0" rpy="0 0 0" />
            <mass value="0.016" />
            <inertia ixx="0.000003368" ixy="0.000000115" ixz="0" iyy="0.000001556" iyz="0"
                izz="0.000002863" />
        </inertial>
    </link>

    <joint name="j00" type="revolute">
        <origin xyz="-0.0122 0.03810 0.01450" rpy="-1.57079 0 1.57079" />
        <parent link="mcp_joint" />
        <child link="pip" />
        <axis xyz="0 0 -1" />
        <limit effort="0.95" velocity="8.48" lower="-1.047" upper="1.047" />
        <joint_properties friction="0.0" />
    </joint>
    <joint name="j01" type="revolute">
        <origin xyz="-0.0070 0.0230 -0.0187" rpy="1.57079 1.57079 0" />
        <parent link="palm_lower" />
        <child link="mcp_joint" />
        <axis xyz="0 0 -1" />
        <limit effort="0.95" velocity="8.48" lower="-0.314" upper="2.23" />
        <joint_properties friction="0.0" />
    </joint>
    <joint name="j02" type="revolute">
        <origin xyz="0.015 0.0143 -0.013" rpy="1.57079 -1.57079 0" />
        <parent link="pip" />
        <child link="dip" />
        <axis xyz="0 0 -1" />
        <limit effort="0.95" velocity="8.48" lower="-0.506" upper="1.885" />
        <joint_properties friction="0.0" />
    </joint>
    <joint name="j03" type="revolute">
        <origin xyz="0 -0.0361 0.0002" rpy="0 0 0" />
        <parent link="dip" />
        <child link="tip_base" />
        <axis xyz="0 0 -1" />
        <limit effort="0.95" velocity="8.48" lower="-0.366" upper="2.042" />
        <joint_properties friction="0.0" />
    </joint>
    <joint name="if_tip" type="fixed" dont_collapse="true">
        <origin xyz="-0.010 -0.048 0.014499" rpy="0 0 0 " />
        <parent link="tip_base" />
        <child link="fingertip_if" />
    </joint>


    <link name="mcp_joint_2">
        <visual>
            <origin xyz="0.0084 0.0077 0.01465" rpy="0 0 0" />
            <geometry>
                <mesh filename="meshes/leap/mcp_joint.obj" />
            </geometry>
        </visual>
        <collision>            <!-- mcp_joint -->
            <origin xyz="0 0.018 0.0147" rpy="0 0 0" />
            <geometry>
                <box size="0.02 0.006 0.034" />
            </geometry>
        </collision>
        <collision>
            <origin xyz="-0.027 0.042 0.015" rpy="0 0 0" />
            <geometry>
                <box size="0.028 0.04 0.02" />
            </geometry>
        </collision>
        <collision>
            <origin xyz="-0.0262 0.02 0.0146" rpy="0 0 0" />
            <geometry>
                <box size="0.034 0.006 0.02" />
            </geometry>
        </collision>
        <collision>
            <origin xyz="-0.0295 0.035 0.029" rpy="0 0 0" />
            <geometry>
                <box size="0.02 0.024 0.008" />
            </geometry>
        </collision>
        <collision>
            <origin xyz="0 0.005 0.03" rpy="0 0 0" />
            <geometry>
                <box size="0.014 0.02 0.004" />
            </geometry>
        </collision>
        <collision>
            <origin xyz="0 0.005 -0.001" rpy="0 0 0" />
            <geometry>
                <box size="0.014 0.02 0.004" />
            </geometry>
        </collision>
        <inertial>
            <origin xyz="0 0 0" rpy="0 0 0" />
            <mass value="0.044" />
            <inertia ixx="0.000011499" ixy="0.000003049" ixz="0.000000121" iyy="0.000007796"
                iyz="0.000000112" izz="0.000014759" />
        </inertial>
    </link>
    <link name="pip_2">
        <visual>
            <origin xyz="0.0096 0.0003 0.0007" rpy="-1.57079 -1.57079 0" />
            <geometry>
                <mesh filename="meshes/leap/pip.obj" />
            </geometry>
        </visual>
        <collision>            <!-- pip -->
            <origin xyz="0.0075 -0.0002 -0.011" rpy="0 0 0" />
            <geometry>
                <box size="0.034 0.026 0.022" />
            </geometry>
        </collision>
        <inertial>
            <origin xyz="0 0 0" rpy="0 0 0" />
            <mass value="0.032" />
            <inertia ixx="0.000004798" ixy="0.000000012" ixz="0.000000004" iyy="0.000002862"
                iyz="0.000000011" izz="0.000004234" />
        </inertial>
    </link>
    <link name="dip_2">
        <visual>
            <origin xyz="0.0211 -0.0084 0.0097" rpy="-3.14159 0 0" />
            <geometry>
                <mesh filename="meshes/leap/dip.obj" />
            </geometry>
        </visual>
        <collision>            <!-- dip -->
            <origin xyz="0 -0.02 0.015" rpy="0 0 0" />
            <geometry>
                <box size="0.016 0.006 0.026" />
            </geometry>
        </collision>
        <collision>
            <origin xyz="0 -0.016 0.015" rpy="0 0 0" />
            <geometry>
                <box size="0.02 0.004 0.034" />
            </geometry>
        </collision>
        <collision>
            <origin xyz="0 -0.0045 0.03" rpy="0 0 0" />
            <geometry>
                <box size="0.014 0.02 0.004" />
            </geometry>
        </collision>
        <collision>
            <origin xyz="0 -0.0045 0" rpy="0 0 0" />
            <geometry>
                <box size="0.014 0.02 0.004" />
            </geometry>
        </collision>
        <collision>
            <origin xyz="0.0075 -0.035 0.015" rpy="0 0 0" />
            <geometry>
                <box size="0.034 0.022 0.026" />
            </geometry>
        </collision>
        <inertial>
            <origin xyz="0 0 0" rpy="0 0 0" />
            <mass value="0.037" />
            <inertia ixx="0.000005542" ixy="-0.000000607" ixz="-0.000000017" iyy="0.000005727"
                iyz="-0.000000023" izz="0.000006682" />
        </inertial>
    </link>

    <link name="tip_base_2">
        <visual>
            <origin xyz="0 -0.014 0.014499" rpy="3.14159 0 0 " />
            <geometry>
                <mesh filename="./meshes/leap/tip_base.obj" />
            </geometry>
        </visual>
        <collision>
            <origin xyz="0 -0.017 0.015" rpy="0 0 0" />
            <geometry>
                <box size="0.02 0.006 0.03" />
            </geometry>
        </collision>
        <collision>
            <origin xyz="0 -0.006 0.03" rpy="0 0 0" />
            <geometry>
                <box size="0.014 0.022 0.004" />
            </geometry>
        </collision>
        <collision>
            <origin xyz="0 -0.006 -0.001" rpy="0 0 0" />
            <geometry>
                <box size="0.014 0.022 0.004" />
            </geometry>
        </collision>
        <inertial>
            <origin xyz="0 0 0" rpy="0 0 0" />
            <mass value="0.008" />
            <inertia ixx="0.000003368" ixy="0.000000115" ixz="0" iyy="0.000001556" iyz="0"
                izz="0.000002863" />
        </inertial>
    </link>
    <link name="fingertip_mf">
        <visual>
            <origin xyz="0 0 0" rpy="3.14159 0 -1.57080" />
            <geometry>
                <mesh filename="./meshes/leap/DotTip.dae" />
            </geometry>
        </visual>
        <collision>
            <origin xyz="0 0 0" rpy="3.14159 0 -1.57080" />
            <geometry>
                <mesh filename="./meshes/leap/DotTip.dae" />
            </geometry>
        </collision>
        <inertial>
            <origin xyz="0 0 0" rpy="0 0 0" />
            <mass value="0.016" />
            <inertia ixx="0.000003368" ixy="0.000000115" ixz="0" iyy="0.000001556" iyz="0"
                izz="0.000002863" />
        </inertial>
    </link>

    <joint name="j04" type="revolute">
        <origin xyz="-0.0122 0.0381 0.0145" rpy="-1.57079 0 1.57079" />
        <parent link="mcp_joint_2" />
        <child link="pip_2" />
        <axis xyz="0 0 -1" />
        <limit effort="0.95" velocity="8.48" lower="-1.047" upper="1.047" />
        <joint_properties friction="0.0" />
    </joint>
    <joint name="j05" type="revolute">
        <origin xyz="-0.0071 -0.0224 -0.0187" rpy="1.57079 1.57079 0" />
        <parent link="palm_lower" />
        <child link="mcp_joint_2" />
        <axis xyz="0 0 -1" />
        <limit effort="0.95" velocity="8.48" lower="-0.314" upper="2.23" />
        <joint_properties friction="0.0" />
    </joint>
    <joint name="j06" type="revolute">
        <origin xyz="0.015 0.0143 -0.013" rpy="1.57079 -1.57079 0" />
        <parent link="pip_2" />
        <child link="dip_2" />
        <axis xyz="0 0 -1" />
        <limit effort="0.95" velocity="8.48" lower="-0.506" upper="1.885" />
        <joint_properties friction="0.0" />
    </joint>
    <joint name="j07" type="revolute">
        <origin xyz="0 -0.0361 0.0002" rpy="0 0 0" />
        <parent link="dip_2" />
        <child link="tip_base_2" />
        <axis xyz="0 0 -1" />
        <limit effort="0.95" velocity="8.48" lower="-0.366" upper="2.042" />
        <joint_properties friction="0.0" />
    </joint>
    <joint name="mf_tip" type="fixed" dont_collapse="true">
        <origin xyz="-0.010 -0.048 0.014499" rpy="0 0 0 " />
        <parent link="tip_base_2" />
        <child link="fingertip_mf" />
    </joint>
    <link name="mcp_joint_3">
        <visual>
            <origin xyz="0.0084 0.0077 0.01465" rpy="0 0 0" />
            <geometry>
                <mesh filename="meshes/leap/mcp_joint.obj" />
            </geometry>
        </visual>
        <collision>            <!-- mcp_joint -->
            <origin xyz="0 0.018 0.0147" rpy="0 0 0" />
            <geometry>
                <box size="0.02 0.006 0.034" />
            </geometry>
        </collision>
        <collision>
            <origin xyz="-0.027 0.042 0.015" rpy="0 0 0" />
            <geometry>
                <box size="0.028 0.04 0.02" />
            </geometry>
        </collision>
        <collision>
            <origin xyz="-0.0262 0.02 0.0146" rpy="0 0 0" />
            <geometry>
                <box size="0.034 0.006 0.02" />
            </geometry>
        </collision>
        <collision>
            <origin xyz="-0.0295 0.035 0.029" rpy="0 0 0" />
            <geometry>
                <box size="0.02 0.024 0.008" />
            </geometry>
        </collision>
        <collision>
            <origin xyz="0 0.005 0.03" rpy="0 0 0" />
            <geometry>
                <box size="0.014 0.02 0.004" />
            </geometry>
        </collision>
        <collision>
            <origin xyz="0 0.005 -0.001" rpy="0 0 0" />
            <geometry>
                <box size="0.014 0.02 0.004" />
            </geometry>
        </collision>
        <inertial>
            <origin xyz="0 0 0" rpy="0 0 0" />
            <mass value="0.044" />
            <inertia ixx="0.000011499" ixy="0.000003049" ixz="0.000000121" iyy="0.000007796"
                iyz="0.000000112" izz="0.000014759" />
        </inertial>
    </link>
    <link name="pip_3">
        <visual>
            <origin xyz="0.0096 0.0003 0.0007" rpy="-1.57079 -1.57079 0" />
            <geometry>
                <mesh filename="meshes/leap/pip.obj" />
            </geometry>
        </visual>
        <collision>            <!-- pip -->
            <origin xyz="0.0075 -0.0002 -0.011" rpy="0 0 0" />
            <geometry>
                <box size="0.034 0.026 0.022" />
            </geometry>
        </collision>
        <inertial>
            <origin xyz="0 0 0" rpy="0 0 0" />
            <mass value="0.032" />
            <inertia ixx="0.000004798" ixy="0.000000012" ixz="0.000000004" iyy="0.000002862"
                iyz="0.000000011" izz="0.000004234" />
        </inertial>
    </link>
    <link name="dip_3">
        <visual>
            <origin xyz="0.0211 -0.0084 0.0097" rpy="-3.14159 0 0" />
            <geometry>
                <mesh filename="meshes/leap/dip.obj" />
            </geometry>
        </visual>
        <collision>            <!-- dip -->
            <origin xyz="0 -0.02 0.015" rpy="0 0 0" />
            <geometry>
                <box size="0.016 0.006 0.026" />
            </geometry>
        </collision>
        <collision>
            <origin xyz="0 -0.016 0.015" rpy="0 0 0" />
            <geometry>
                <box size="0.02 0.004 0.034" />
            </geometry>
        </collision>
        <collision>
            <origin xyz="0 -0.0045 0.03" rpy="0 0 0" />
            <geometry>
                <box size="0.014 0.02 0.004" />
            </geometry>
        </collision>
        <collision>
            <origin xyz="0 -0.0045 0" rpy="0 0 0" />
            <geometry>
                <box size="0.014 0.02 0.004" />
            </geometry>
        </collision>
        <collision>
            <origin xyz="0.0075 -0.035 0.015" rpy="0 0 0" />
            <geometry>
                <box size="0.034 0.022 0.026" />
            </geometry>
        </collision>
        <inertial>
            <origin xyz="0 0 0" rpy="0 0 0" />
            <mass value="0.037" />
            <inertia ixx="0.000005542" ixy="-0.000000607" ixz="-0.000000017" iyy="0.000005727"
                iyz="-0.000000023" izz="0.000006682" />
        </inertial>
    </link>
    <link name="tip_base_3">
        <visual>
            <origin xyz="0 -0.014 0.014499" rpy="3.14159 0 0 " />
            <geometry>
                <mesh filename="./meshes/leap/tip_base.obj" />
            </geometry>
        </visual>
        <collision>
            <origin xyz="0 -0.017 0.015" rpy="0 0 0" />
            <geometry>
                <box size="0.02 0.006 0.03" />
            </geometry>
        </collision>
        <collision>
            <origin xyz="0 -0.006 0.03" rpy="0 0 0" />
            <geometry>
                <box size="0.014 0.022 0.004" />
            </geometry>
        </collision>
        <collision>
            <origin xyz="0 -0.006 -0.001" rpy="0 0 0" />
            <geometry>
                <box size="0.014 0.022 0.004" />
            </geometry>
        </collision>
        <inertial>
            <origin xyz="0 0 0" rpy="0 0 0" />
            <mass value="0.008" />
            <inertia ixx="0.000003368" ixy="0.000000115" ixz="0" iyy="0.000001556" iyz="0"
                izz="0.000002863" />
        </inertial>
    </link>
    <link name="fingertip_rf">
        <visual>
            <origin xyz="0 0 0" rpy="3.14159 0 -1.57080" />
            <geometry>
                <mesh filename="./meshes/leap/DotTip.dae" />
            </geometry>
        </visual>
        <collision>
            <origin xyz="0 0 0" rpy="3.14159 0 -1.57080" />
            <geometry>
                <mesh filename="./meshes/leap/DotTip.dae" />
            </geometry>
        </collision>
        <inertial>
            <origin xyz="0 0 0" rpy="0 0 0" />
            <mass value="0.016" />
            <inertia ixx="0.000003368" ixy="0.000000115" ixz="0" iyy="0.000001556" iyz="0"
                izz="0.000002863" />
        </inertial>
    </link>
    <joint name="j08" type="revolute">
        <origin xyz="-0.0122 0.0381 0.0145" rpy="-1.57079 0 1.57079" />
        <parent link="mcp_joint_3" />
        <child link="pip_3" />
        <axis xyz="0 0 -1" />
        <limit effort="0.95" velocity="8.48" lower="-1.047" upper="1.047" />
        <joint_properties friction="0.0" />
    </joint>
    <joint name="j09" type="revolute">
        <origin xyz="-0.00709 -0.0678 -0.0187" rpy="1.57079 1.57079 0" />
        <parent link="palm_lower" />
        <child link="mcp_joint_3" />
        <axis xyz="0 0 -1" />
        <limit effort="0.95" velocity="8.48" lower="-0.314" upper="2.23" />
        <joint_properties friction="0.0" />
    </joint>
    <joint name="j10" type="revolute">
        <origin xyz="0.015 0.0143 -0.013" rpy="1.57079 -1.57079 0" />
        <parent link="pip_3" />
        <child link="dip_3" />
        <axis xyz="0 0 -1" />
        <limit effort="0.95" velocity="8.48" lower="-0.506" upper="1.885" />
        <joint_properties friction="0.0" />
    </joint>
    <joint name="j11" type="revolute">
        <origin xyz="0 -0.03609 0.0002" rpy="0 0 0" />
        <parent link="dip_3" />
        <child link="tip_base_3" />
        <axis xyz="0 0 -1" />
        <limit effort="0.95" velocity="8.48" lower="-0.366" upper="2.042" />
        <joint_properties friction="0.0" />
    </joint>
    <joint name="rf_tip" type="fixed" dont_collapse="true">
        <origin xyz="-0.010 -0.048 0.014499" rpy="0 0 0 " />
        <parent link="tip_base_3" />
        <child link="fingertip_rf" />
    </joint>


    <link name="thumb_temp_base">
        <visual>
            <origin xyz="-0.0053 0.0003 0.00078" rpy="-1.57079 -1.57079 0" />
            <geometry>
                <mesh filename="meshes/leap/pip.obj" />
            </geometry>
        </visual>
        <collision>            <!-- pip -->
            <origin xyz="-0.0075 -0.0002 -0.011" rpy="0 0 0" />
            <geometry>
                <box size="0.034 0.026 0.022" />
            </geometry>
        </collision>
        <inertial>
            <origin xyz="0 0 0" rpy="0 0 0" />
            <mass value="0.032" />
            <inertia ixx="0.000004798" ixy="0.000000012" ixz="0.000000004" iyy="0.000002862"
                iyz="0.000000011" izz="0.000004234" />
        </inertial>
    </link>
    <link name="thumb_pip">
        <visual>
            <origin xyz="0.01196 0 -0.0158" rpy="1.57079 0 0" />
            <geometry>
                <mesh filename="meshes/leap/thumb_pip.obj" />
            </geometry>
        </visual>
        <collision>            <!-- thumb_pip -->
            <origin xyz="0 0 -0.0015" rpy="0 0 0" />
            <geometry>
                <box size="0.018 0.033 0.004" />
            </geometry>
        </collision>
        <collision>
            <origin xyz="0 -0.015 -0.013" rpy="0 0 0" />
            <geometry>
                <box size="0.014 0.004 0.02" />
            </geometry>
        </collision>
        <collision>
            <origin xyz="0 0.015 -0.013" rpy="0 0 0" />
            <geometry>
                <box size="0.014 0.004 0.02" />
            </geometry>
        </collision>
        <inertial>
            <origin xyz="0 0 0" rpy="0 0 0" />
            <mass value="0.003" />
            <inertia ixx="0.000000593" ixy="0" ixz="0" iyy="0.000000549" iyz="0" izz="0.000000224" />
        </inertial>
    </link>
    <link name="thumb_dip">
        <visual>
            <origin xyz="0.0439 0.0579 -0.0086" rpy="0 0 0" />
            <geometry>
                <mesh filename="meshes/leap/thumb_dip.obj" />
            </geometry>
        </visual>
        <collision>            <!-- thumb_dip -->
            <origin xyz="0 0.0105 -0.014" rpy="0 0 0" />
            <geometry>
                <box size="0.02 0.04 0.024" />
            </geometry>
        </collision>
        <collision>
            <origin xyz="0 0.031 -0.015" rpy="0 0 0" />
            <geometry>
                <box size="0.02 0.004 0.032" />
            </geometry>
        </collision>
        <collision>
            <origin xyz="0 0.042 0.001" rpy="0 0 0" />
            <geometry>
                <box size="0.014 0.02 0.004" />
            </geometry>
        </collision>
        <collision>
            <origin xyz="0 0.042 -0.029" rpy="0 0 0" />
            <geometry>
                <box size="0.014 0.02 0.004" />
            </geometry>
        </collision>
        <collision>
            <origin xyz="-0.0135 0.0175 -0.011656" rpy="0 0 0" />
            <geometry>
                <box size="0.01 0.024 0.018" />
            </geometry>
        </collision>
        <inertial>
            <origin xyz="0 0 0" rpy="0 0 0" />
            <mass value="0.038" />
            <inertia ixx="0.000008474" ixy="0.000000241" ixz="0.000000026" iyy="0.000003841"
                iyz="0.000000025" izz="0.000007679" />
        </inertial>
    </link>

    <link name="thumb_tip_base">
        <visual>
            <origin xyz="0 0 -0.0065" rpy="0 0 0 " />
            <geometry>
                <mesh filename="./meshes/leap/thumb_tip_base.obj" />
            </geometry>
        </visual>
        <collision>
            <origin xyz="0 -0.0085 -0.015" rpy="0 0 0" />
            <geometry>
                <box size="0.02 0.036 0.024" />
            </geometry>
        </collision>
        <collision>
            <origin xyz="0 -0.029 -0.014" rpy="0 0 0" />
            <geometry>
                <box size="0.02 0.004 0.03" />
            </geometry>
        </collision>
        <collision>
            <origin xyz="0.015 -0.0175 -0.0115" rpy="0 0 0" />
            <geometry>
                <box size="0.008 0.024 0.018" />
            </geometry>
        </collision>
        <inertial>
            <origin xyz="0 0 0" rpy="0 0 0" />
            <mass value="0.008" />
            <inertia ixx="0.000003368" ixy="0.000000115" ixz="0" iyy="0.000001556" iyz="0"
                izz="0.000002863" />
        </inertial>
    </link>
    <link name="thumb_fingertip">
        <visual>
            <origin xyz="0 0 0 " rpy="3.14159 0 -1.57080" />
            <geometry>
                <mesh filename="./meshes/leap/DotTip-thumb.dae" />
            </geometry>
        </visual>
        <collision>
            <origin xyz="0 0 0 " rpy="3.14159 0 -1.57080" />
            <geometry>
                <mesh filename="./meshes/leap/DotTip-thumb.dae" />
            </geometry>
        </collision>
        <inertial>
            <origin xyz="0 0 0" rpy="0 0 0" />
            <mass value="0.016" />
            <inertia ixx="0.000003368" ixy="0.000000115" ixz="0" iyy="0.000001556" iyz="0"
                izz="0.000002863" />
        </inertial>
    </link>
    <joint name="j12" type="revolute">
        <origin xyz="-0.0693 -0.0012 -0.0216" rpy="0 1.57079 0" />
        <parent link="palm_lower" />
        <child link="thumb_temp_base" />
        <axis xyz="0 0 -1" />
        <limit effort="0.95" velocity="8.48" lower="-0.349" upper="2.094" />
        <joint_properties friction="0.0" />
    </joint>
    <joint name="j13" type="revolute">
        <origin xyz="0 0.0143 -0.013" rpy="1.57079 -1.57079 0" />
        <parent link="thumb_temp_base" />
        <child link="thumb_pip" />
        <axis xyz="0 0 -1" />
        <limit effort="0.95" velocity="8.48" lower="-0.47" upper="2.443" />
        <joint_properties friction="0.0" />
    </joint>
    <joint name="j14" type="revolute">
        <origin xyz="0 0.0145 -0.017" rpy="-1.57079 0 0" />
        <parent link="thumb_pip" />
        <child link="thumb_dip" />
        <axis xyz="0 0 -1" />
        <limit effort="0.95" velocity="8.48" lower="-1.20" upper="1.90" />
        <joint_properties friction="0.0" />
    </joint>
    <joint name="j15" type="revolute">
        <origin xyz="0 0.0466 0.0002" rpy="0 0 3.14159" />
        <parent link="thumb_dip" />
        <child link="thumb_tip_base" />
        <axis xyz="0 0 -1" />
        <limit effort="0.95" velocity="8.48" lower="-1.34" upper="1.88" />
        <joint_properties friction="0.0" />
    </joint>
    <joint name="tf_tip" type="fixed" dont_collapse="true">
        <origin xyz="-0.0102  -0.0645 -0.0145" rpy="0 0 0 " />
        <parent link="thumb_tip_base" />
        <child link="thumb_fingertip" />
    </joint>

    <!--  virtual auxiliary link-->
    <link name="if_tip_center" />
    <link name="mf_tip_center" />
    <link name="rf_tip_center" />
    <link name="tf_tip_center" />

    <joint name="if_tip_center_joint" type="fixed" dont_collapse="true">
        <parent link="fingertip_if" />
        <child link="if_tip_center" />
        <origin xyz="0 0 -0.020" rpy="-1.570796 0 -1.570796" />
    </joint>
    <joint name="mf_tip_center_joint" type="fixed" dont_collapse="true">
        <parent link="fingertip_mf" />
        <child link="mf_tip_center" />
        <origin xyz="0 0 -0.020" rpy="-1.570796 0 -1.570796" />
    </joint>
    <joint name="rf_tip_center_joint" type="fixed" dont_collapse="true">
        <parent link="fingertip_rf" />
        <child link="rf_tip_center" />
        <origin xyz="0 0 -0.020" rpy="-1.570796 0 -1.570796" />
    </joint>
    <joint name="tf_tip_center_joint" type="fixed" dont_collapse="true">
        <parent link="thumb_fingertip" />
        <child link="tf_tip_center" />
        <origin xyz="0 0 -0.020" rpy="-1.570796 0 -1.570796" />
    </joint>


</robot>